Workbook

Sheet Raw_Data
A1: InvoiceNo | B1: StockCode | C1: Description | D1: Quantity | E1: InvoiceDate | F1: UnitPrice | G1: CustomerID | H1: Country | I1: Valid_Transaction | J1: Transaction_Month | K1: Transaction_Value | L1: Customer_Month_Key
A2: 554615 | B2: 20698 | C2: SET 7 BABUSHKA NESTING BOXES | D2: 21 | E2: 40513.333 | F2: 2.1 | G2: 12714 | H2: United Kingdom | I2: =IF(AND(LEFT(OnlineRetail[[#This Row],[InvoiceNo]],1)<>"C",OnlineRetail[[#This Row],[CustomerID]]<>""),"Yes","No") -> Yes | J2: =EOMONTH(OnlineRetail[[#This Row],[InvoiceDate]],-1)+1 -> 40513 | K2: =OnlineRetail[[#This Row],[Quantity]]*OnlineRetail[[#This Row],[UnitPrice]] -> 44.1 | L2: =IF(I2="Yes",G2&"|"&TEXT(J2,"mmm-yyyy"),"") -> 12714|Dec-2010
A3: 555393 | B3: 89273 | C3: CREAM CUPID HEARTS COAT HANGER | D3: 14 | E3: 40513.352 | F3: 2.55 | G3: 13585 | H3: United Kingdom | I3: =IF(AND(LEFT(OnlineRetail[[#This Row],[InvoiceNo]],1)<>"C",OnlineRetail[[#This Row],[CustomerID]]<>""),"Yes","No") -> Yes | J3: =EOMONTH(OnlineRetail[[#This Row],[InvoiceDate]],-1)+1 -> 40513 | K3: =OnlineRetail[[#This Row],[Quantity]]*OnlineRetail[[#This Row],[UnitPrice]] -> 35.7 | L3: =IF(I3="Yes",G3&"|"&TEXT(J3,"mmm-yyyy"),"") -> 13585|Dec-2010
A4: 542008 | B4: 93239 | C4: BOX OF 6 ASSORTED COLOUR TEASPOONS | D4: 13 | E4: 40513.443 | F4: 5.95 | G4: 14152 | H4: United Kingdom | I4: =IF(AND(LEFT(OnlineRetail[[#This Row],[InvoiceNo]],1)<>"C",OnlineRetail[[#This Row],[CustomerID]]<>""),"Yes","No") -> Yes | J4: =EOMONTH(OnlineRetail[[#This Row],[InvoiceDate]],-1)+1 -> 40513 | K4: =OnlineRetail[[#This Row],[Quantity]]*OnlineRetail[[#This Row],[UnitPrice]] -> 77.35 | L4: =IF(I4="Yes",G4&"|"&TEXT(J4,"mmm-yyyy"),"") -> 14152|Dec-2010
A5: 555648 | B5: 62867 | C5: KNITTED UNION FLAG HOT WATER BOTTLE | D5: 23 | E5: 40513.462 | F5: 2.55 | G5: 12929 | H5: France | I5: =IF(AND(LEFT(OnlineRetail[[#This Row],[InvoiceNo]],1)<>"C",OnlineRetail[[#This Row],[CustomerID]]<>""),"Yes","No") -> Yes | J5: =EOMONTH(OnlineRetail[[#This Row],[InvoiceDate]],-1)+1 -> 40513 | K5: =OnlineRetail[[#This Row],[Quantity]]*OnlineRetail[[#This Row],[UnitPrice]] -> 58.65 | L5: =IF(I5="Yes",G5&"|"&TEXT(J5,"mmm-yyyy"),"") -> 12929|Dec-2010
A6: 543791 | B6: 54644 | C6: HOME BUILDING BLOCK WORD | D6: 15 | E6: 40513.492 | F6: 2.55 | G6: 14321 | H6: United Kingdom | I6: =IF(AND(LEFT(OnlineRetail[[#This Row],[InvoiceNo]],1)<>"C",OnlineRetail[[#This Row],[CustomerID]]<>""),"Yes","No") -> Yes | J6: =EOMONTH(OnlineRetail[[#This Row],[InvoiceDate]],-1)+1 -> 40513 | K6: =OnlineRetail[[#This Row],[Quantity]]*OnlineRetail[[#This Row],[UnitPrice]] -> 38.25 | L6: =IF(I6="Yes",G6&"|"&TEXT(J6,"mmm-yyyy"),"") -> 14321|Dec-2010
A7: 545517 | B7: 96441 | C7: FELTCRAFT PRINCESS CHARLOTTE DOLL | D7: 1 | E7: 40513.604 | F7: 4.95 | G7: 13645 | H7: Netherlands | I7: =IF(AND(LEFT(OnlineRetail[[#This Row],[InvoiceNo]],1)<>"C",OnlineRetail[[#This Row],[CustomerID]]<>""),"Yes","No") -> Yes | J7: =EOMONTH(OnlineRetail[[#This Row],[InvoiceDate]],-1)+1 -> 40513 | K7: =OnlineRetail[[#This Row],[Quantity]]*OnlineRetail[[#This Row],[UnitPrice]] -> 4.95 | L7: =IF(I7="Yes",G7&"|"&TEXT(J7,"mmm-yyyy"),"") -> 13645|Dec-2010
A8: 537935 | B8: 88164 | C8: JAM MAKING SET WITH JARS | D8: 11 | E8: 40513.642 | F8: 5.95 | G8: 14258 | H8: Spain | I8: =IF(AND(LEFT(OnlineRetail[[#This Row],[InvoiceNo]],1)<>"C",OnlineRetail[[#This Row],[CustomerID]]<>""),"Yes","No") -> Yes | J8: =EOMONTH(OnlineRetail[[#This Row],[InvoiceDate]],-1)+1 -> 40513 | K8: =OnlineRetail[[#This Row],[Quantity]]*OnlineRetail[[#This Row],[UnitPrice]] -> 65.45 | L8: =IF(I8="Yes",G8&"|"&TEXT(J8,"mmm-yyyy"),"") -> 14258|Dec-2010
A9: 555208 | B9: 98428 | C9: POPPY'S PLAYHOUSE KITCHEN | D9: 22 | E9: 40513.685 | F9: 4.95 | G9: 13809 | H9: United Kingdom | I9: =IF(AND(LEFT(OnlineRetail[[#This Row],[InvoiceNo]],1)<>"C",OnlineRetail[[#This Row],[CustomerID]]<>""),"Yes","No") -> Yes | J9: =EOMONTH(OnlineRetail[[#This Row],[InvoiceDate]],-1)+1 -> 40513 | K9: =OnlineRetail[[#This Row],[Quantity]]*OnlineRetail[[#This Row],[UnitPrice]] -> 108.9 | L9: =IF(I9="Yes",G9&"|"&TEXT(J9,"mmm-yyyy"),"") -> 13809|Dec-2010
A10: 540489 | B10: 98643 | C10: GLASS STAR FROSTED T-LIGHT HOLDER | D10: 13 | E10: 40513.695 | F10: 4.95 | G10: 12472 | H10: United Kingdom | I10: =IF(AND(LEFT(OnlineRetail[[#This Row],[InvoiceNo]],1)<>"C",OnlineRetail[[#This Row],[CustomerID]]<>""),"Yes","No") -> Yes | J10: =EOMONTH(OnlineRetail[[#This Row],[InvoiceDate]],-1)+1 -> 40513 | K10: =OnlineRetail[[#This Row],[Quantity]]*OnlineRetail[[#This Row],[UnitPrice]] -> 64.35 | L10: =IF(I10="Yes",G10&"|"&TEXT(J10,"mmm-yyyy"),"") -> 12472|Dec-2010
A11: 553424 | B11: 51302 | C11: GLASS STAR FROSTED T-LIGHT HOLDER | D11: 14 | E11: 40513.713 | F11: 2.1 | G11: 12964 | H11: Germany | I11: =IF(AND(LEFT(OnlineRetail[[#This Row],[InvoiceNo]],1)<>"C",OnlineRetail[[#This Row],[CustomerID]]<>""),"Yes","No") -> Yes | J11: =EOMONTH(OnlineRetail[[#This Row],[InvoiceDate]],-1)+1 -> 40513 | K11: =OnlineRetail[[#This Row],[Quantity]]*OnlineRetail[[#This Row],[UnitPrice]] -> 29.4 | L11: =IF(I11="Yes",G11&"|"&TEXT(J11,"mmm-yyyy"),"") -> 12964|Dec-2010
A12: 544407 | B12: 61719 | C12: RECIPE BOX WITH METAL HEART | D12: 15 | E12: 40513.715 | F12: 9.95 | G12: 13987 | H12: United Kingdom | I12: =IF(AND(LEFT(OnlineRetail[[#This Row],[InvoiceNo]],1)<>"C",OnlineRetail[[#This Row],[CustomerID]]<>""),"Yes","No") -> Yes | J12: =EOMONTH(OnlineRetail[[#This Row],[InvoiceDate]],-1)+1 -> 40513 | K12: =OnlineRetail[[#This Row],[Quantity]]*OnlineRetail[[#This Row],[UnitPrice]] -> 149.25 | L12: =IF(I12="Yes",G12&"|"&TEXT(J12,"mmm-yyyy"),"") -> 13987|Dec-2010
A13: 542183 | B13: 88422 | C13: GLASS STAR FROSTED T-LIGHT HOLDER | D13: 21 | E13: 40513.732 | F13: 2.55 | G13: 13441 | H13: United Kingdom | I13: =IF(AND(LEFT(OnlineRetail[[#This Row],[InvoiceNo]],1)<>"C",OnlineRetail[[#This Row],[CustomerID]]<>""),"Yes","No") -> Yes | J13: =EOMONTH(OnlineRetail[[#This Row],[InvoiceDate]],-1)+1 -> 40513 | K13: =OnlineRetail[[#This Row],[Quantity]]*OnlineRetail[[#This Row],[UnitPrice]] -> 53.55 | L13: =IF(I13="Yes",G13&"|"&TEXT(J13,"mmm-yyyy"),"") -> 13441|Dec-2010
... A44: 554390 | B44: 75764 | C44: RED COAT RACK PARIS FASHION | D44: 15 | E44: 40515.83 | F44: 2.55 | G44: 13863 | H44: United Kingdom | I44: =IF(AND(LEFT(OnlineRetail[[#This Row],[InvoiceNo]],1)<>"C",OnlineRetail[[#This Row],[CustomerID]]<>""),"Yes","No") -> Yes | J44: =EOMONTH(OnlineRetail[[#This Row],[InvoiceDate]],-1)+1 -> 40513 | K44: =OnlineRetail[[#This Row],[Quantity]]*OnlineRetail[[#This Row],[UnitPrice]] -> 38.25 | L44: =IF(I44="Yes",G44&"|"&TEXT(J44,"mmm-yyyy"),"") -> 13863|Dec-2010
A45: C546685 | B45: 33775 | C45: HOME BUILDING BLOCK WORD | D45: 3 | E45: 40516.35 | F45: 1.65 | G45: 12492 | H45: United Kingdom | I45: =IF(AND(LEFT(OnlineRetail[[#This Row],[InvoiceNo]],1)<>"C",OnlineRetail[[#This Row],[CustomerID]]<>""),"Yes","No") -> No | J45: =EOMONTH(OnlineRetail[[#This Row],[InvoiceDate]],-1)+1 -> 40513 | K45: =OnlineRetail[[#This Row],[Quantity]]*OnlineRetail[[#This Row],[UnitPrice]] -> 4.95 | L45: =IF(I45="Yes",G45&"|"&TEXT(J45,"mmm-yyyy"),"")
A46: 554884 | B46: 17202 | C46: CREAM CUPID HEARTS COAT HANGER | D46: 3 | E46: 40516.351 | F46: 3.39 | G46: 14321 | H46: United Kingdom | I46: =IF(AND(LEFT(OnlineRetail[[#This Row],[InvoiceNo]],1)<>"C",OnlineRetail[[#This Row],[CustomerID]]<>""),"Yes","No") -> Yes | J46: =EOMONTH(OnlineRetail[[#This Row],[InvoiceDate]],-1)+1 -> 40513 | K46: =OnlineRetail[[#This Row],[Quantity]]*OnlineRetail[[#This Row],[UnitPrice]] -> 10.17 | L46: =IF(I46="Yes",G46&"|"&TEXT(J46,"mmm-yyyy"),"") -> 14321|Dec-2010
A47: 542705 | B47: 20151 | C47: DOORMAT NEW ENGLAND | D47: 1 | E47: 40516.371 | F47: 1.25 | G47: 12774 | H47: United Kingdom | I47: =IF(AND(LEFT(OnlineRetail[[#This Row],[InvoiceNo]],1)<>"C",OnlineRetail[[#This Row],[CustomerID]]<>""),"Yes","No") -> Yes | J47: =EOMONTH(OnlineRetail[[#This Row],[InvoiceDate]],-1)+1 -> 40513 | K47: =OnlineRetail[[#This Row],[Quantity]]*OnlineRetail[[#This Row],[UnitPrice]] -> 1.25 | L47: =IF(I47="Yes",G47&"|"&TEXT(J47,"mmm-yyyy"),"") -> 12774|Dec-2010
A48: 551922 | B48: 61880 | C48: IVORY KNITTED MUG COSY | D48: 5 | E48: 40516.403 | F48: 2.55 | G48: 13135 | H48: United Kingdom | I48: =IF(AND(LEFT(OnlineRetail[[#This Row],[InvoiceNo]],1)<>"C",OnlineRetail[[#This Row],[CustomerID]]<>""),"Yes","No") -> Yes | J48: =EOMONTH(OnlineRetail[[#This Row],[InvoiceDate]],-1)+1 -> 40513 | K48: =OnlineRetail[[#This Row],[Quantity]]*OnlineRetail[[#This Row],[UnitPrice]] -> 12.75 | L48: =IF(I48="Yes",G48&"|"&TEXT(J48,"mmm-yyyy"),"") -> 13135|Dec-2010
A49: 555772 | B49: 29593 | C49: WHITE HANGING HEART T-LIGHT HOLDER | D49: 20 | E49: 40516.417 | F49: 1.25 | G49: 13044 | H49: Germany | I49: =IF(AND(LEFT(OnlineRetail[[#This Row],[InvoiceNo]],1)<>"C",OnlineRetail[[#This Row],[CustomerID]]<>""),"Yes","No") -> Yes | J49: =EOMONTH(OnlineRetail[[#This Row],[InvoiceDate]],-1)+1 -> 40513 | K49: =OnlineRetail[[#This Row],[Quantity]]*OnlineRetail[[#This Row],[UnitPrice]] -> 25 | L49: =IF(I49="Yes",G49&"|"&TEXT(J49,"mmm-yyyy"),"") -> 13044|Dec-2010
A50: 538773 | B50: 41218 | C50: RED WOOLLY HOTTIE WHITE HEART | D50: 7 | E50: 40516.498 | F50: 2.1 | G50: 14328 | H50: United Kingdom | I50: =IF(AND(LEFT(OnlineRetail[[#This Row],[InvoiceNo]],1)<>"C",OnlineRetail[[#This Row],[CustomerID]]<>""),"Yes","No") -> Yes | J50: =EOMONTH(OnlineRetail[[#This Row],[InvoiceDate]],-1)+1 -> 40513 | K50: =OnlineRetail[[#This Row],[Quantity]]*OnlineRetail[[#This Row],[UnitPrice]] -> 14.7 | L50: =IF(I50="Yes",G50&"|"&TEXT(J50,"mmm-yyyy"),"") -> 14328|Dec-2010
A51: 556290 | B51: 12973 | C51: RED WOOLLY HOTTIE WHITE HEART | D51: 12 | E51: 40516.583 | F51: 4.25 | G51: 14341 | H51: United Kingdom | I51: =IF(AND(LEFT(OnlineRetail[[#This Row],[InvoiceNo]],1)<>"C",OnlineRetail[[#This Row],[CustomerID]]<>""),"Yes","No") -> Yes | J51: =EOMONTH(OnlineRetail[[#This Row],[InvoiceDate]],-1)+1 -> 40513 | K51: =OnlineRetail[[#This Row],[Quantity]]*OnlineRetail[[#This Row],[UnitPrice]] -> 51 | L51: =IF(I51="Yes",G51&"|"&TEXT(J51,"mmm-yyyy"),"") -> 14341|Dec-2010
A52: 547855 | B52: 89273 | C52: GLASS STAR FROSTED T-LIGHT HOLDER | D52: 22 | E52: 40516.594 | F52: 3.39 | G52: 13175 | H52: United Kingdom | I52: =IF(AND(LEFT(OnlineRetail[[#This Row],[InvoiceNo]],1)<>"C",OnlineRetail[[#This Row],[CustomerID]]<>""),"Yes","No") -> Yes | J52: =EOMONTH(OnlineRetail[[#This Row],[InvoiceDate]],-1)+1 -> 40513 | K52: =OnlineRetail[[#This Row],[Quantity]]*OnlineRetail[[#This Row],[UnitPrice]] -> 74.58 | L52: =IF(I52="Yes",G52&"|"&TEXT(J52,"mmm-yyyy"),"") -> 13175|Dec-2010
A53: 538745 | B53: 43918 | C53: JAM MAKING SET WITH JARS | D53: 22 | E53: 40516.603 | F53: 2.1 | G53: 13364 | H53: Germany | I53: =IF(AND(LEFT(OnlineRetail[[#This Row],[InvoiceNo]],1)<>"C",OnlineRetail[[#This Row],[CustomerID]]<>""),"Yes","No") -> Yes | J53: =EOMONTH(OnlineRetail[[#This Row],[InvoiceDate]],-1)+1 -> 40513 | K53: =OnlineRetail[[#This Row],[Quantity]]*OnlineRetail[[#This Row],[UnitPrice]] -> 46.2 | L53: =IF(I53="Yes",G53&"|"&TEXT(J53,"mmm-yyyy"),"") -> 13364|Dec-2010
A54: 544644 | B54: 20151 | C54: WHITE HANGING HEART T-LIGHT HOLDER | D54: 9 | E54: 40516.623 | F54: 2.55 | G54: 13175 | H54: Belgium | I54: =IF(AND(LEFT(OnlineRetail[[#This Row],[InvoiceNo]],1)<>"C",OnlineRetail[[#This Row],[CustomerID]]<>""),"Yes","No") -> Yes | J54: =EOMONTH(OnlineRetail[[#This Row],[InvoiceDate]],-1)+1 -> 40513 | K54: =OnlineRetail[[#This Row],[Quantity]]*OnlineRetail[[#This Row],[UnitPrice]] -> 22.95 | L54: =IF(I54="Yes",G54&"|"&TEXT(J54,"mmm-yyyy"),"") -> 13175|Dec-2010
A55: 538698 | B55: 30919 | C55: POPPY'S PLAYHOUSE KITCHEN | D55: 2 | E55: 40516.656 | F55: 5.95 | G55: 13624 | H55: Germany | I55: =IF(AND(LEFT(OnlineRetail[[#This Row],[InvoiceNo]],1)<>"C",OnlineRetail[[#This Row],[CustomerID]]<>""),"Yes","No") -> Yes | J55: =EOMONTH(OnlineRetail[[#This Row],[InvoiceDate]],-1)+1 -> 40513 | K55: =OnlineRetail[[#This Row],[Quantity]]*OnlineRetail[[#This Row],[UnitPrice]] -> 11.9 | L55: =IF(I55="Yes",G55&"|"&TEXT(J55,"mmm-yyyy"),"") -> 13624|Dec-2010
A56: 546255 | B56: 47836 | C56: LOVE BUILDING BLOCK WORD | D56: 3 | E56: 40516.657 | F56: 4.95 | G56: 12578 | H56: United Kingdom | I56: =IF(AND(LEFT(OnlineRetail[[#This Row],[InvoiceNo]],1)<>"C",OnlineRetail[[#This Row],[CustomerID]]<>""),"Yes","No") -> Yes | J56: =EOMONTH(OnlineRetail[[#This Row],[InvoiceDate]],-1)+1 -> 40513 | K56: =OnlineRetail[[#This Row],[Quantity]]*OnlineRetail[[#This Row],[UnitPrice]] -> 14.85 | L56: =IF(I56="Yes",G56&"|"&TEXT(J56,"mmm-yyyy"),"") -> 12578|Dec-2010
A57: 551492 | B57: 91323 | C57: WHITE HANGING HEART T-LIGHT HOLDER | D57: 7 | E57: 40516.698 | F57: 2.1 | G57: 13871 | H57: France | I57: =IF(AND(LEFT(OnlineRetail[[#This Row],[InvoiceNo]],1)<>"C",OnlineRetail[[#This Row],[CustomerID]]<>""),"Yes","No") -> Yes | J57: =EOMONTH(OnlineRetail[[#This Row],[InvoiceDate]],-1)+1 -> 40513 | K57: =OnlineRetail[[#This Row],[Quantity]]*OnlineRetail[[#This Row],[UnitPrice]] -> 14.7 | L57: =IF(I57="Yes",G57&"|"&TEXT(J57,"mmm-yyyy"),"") -> 13871|Dec-2010
... A62: 553088 | B62: 10178 | C62: IVORY KNITTED MUG COSY | D62: 3 | E62: 40517.494 | F62: 7.95 | G62: 13645 | H62: United Kingdom | I62: =IF(AND(LEFT(OnlineRetail[[#This Row],[InvoiceNo]],1)<>"C",OnlineRetail[[#This Row],[CustomerID]]<>""),"Yes","No") -> Yes | J62: =EOMONTH(OnlineRetail[[#This Row],[InvoiceDate]],-1)+1 -> 40513 | K62: =OnlineRetail[[#This Row],[Quantity]]*OnlineRetail[[#This Row],[UnitPrice]] -> 23.85 | L62: =IF(I62="Yes",G62&"|"&TEXT(J62,"mmm-yyyy"),"") -> 13645|Dec-2010
A63: C537705 | B63: 45858 | C63: FELTCRAFT PRINCESS CHARLOTTE DOLL | D63: 16 | E63: 40517.597 | F63: 4.25 | G63: 13315 | H63: United Kingdom | I63: =IF(AND(LEFT(OnlineRetail[[#This Row],[InvoiceNo]],1)<>"C",OnlineRetail[[#This Row],[CustomerID]]<>""),"Yes","No") -> No | J63: =EOMONTH(OnlineRetail[[#This Row],[InvoiceDate]],-1)+1 -> 40513 | K63: =OnlineRetail[[#This Row],[Quantity]]*OnlineRetail[[#This Row],[UnitPrice]] -> 68 | L63: =IF(I63="Yes",G63&"|"&TEXT(J63,"mmm-yyyy"),"")
A64: 552985 | B64: 41676 | C64: HOME BUILDING BLOCK WORD | D64: 11 | E64: 40517.614 | F64: 1.25 | G64: 12625 | H64: United Kingdom | I64: =IF(AND(LEFT(OnlineRetail[[#This Row],[InvoiceNo]],1)<>"C",OnlineRetail[[#This Row],[CustomerID]]<>""),"Yes","No") -> Yes | J64: =EOMONTH(OnlineRetail[[#This Row],[InvoiceDate]],-1)+1 -> 40513 | K64: =OnlineRetail[[#This Row],[Quantity]]*OnlineRetail[[#This Row],[UnitPrice]] -> 13.75 | L64: =IF(I64="Yes",G64&"|"&TEXT(J64,"mmm-yyyy"),"") -> 12625|Dec-2010
A65: 555896 | B65: 19418 | C65: CREAM CUPID HEARTS COAT HANGER | D65: 12 | E65: 40517.615 | F65: 1.25 | G65: 12742 | H65: United Kingdom | I65: =IF(AND(LEFT(OnlineRetail[[#This Row],[InvoiceNo]],1)<>"C",OnlineRetail[[#This Row],[CustomerID]]<>""),"Yes","No") -> Yes | J65: =EOMONTH(OnlineRetail[[#This Row],[InvoiceDate]],-1)+1 -> 40513 | K65: =OnlineRetail[[#This Row],[Quantity]]*OnlineRetail[[#This Row],[UnitPrice]] -> 15 | L65: =IF(I65="Yes",G65&"|"&TEXT(J65,"mmm-yyyy"),"") -> 12742|Dec-2010
A66: 547336 | B66: 83681 | C66: DOORMAT NEW ENGLAND | D66: 21 | E66: 40517.736 | F66: 3.39 | G66: 13696 | H66: United Kingdom | I66: =IF(AND(LEFT(OnlineRetail[[#This Row],[InvoiceNo]],1)<>"C",OnlineRetail[[#This Row],[CustomerID]]<>""),"Yes","No") -> Yes | J66: =EOMONTH(OnlineRetail[[#This Row],[InvoiceDate]],-1)+1 -> 40513 | K66: =OnlineRetail[[#This Row],[Quantity]]*OnlineRetail[[#This Row],[UnitPrice]] -> 71.19 | L66: =IF(I66="Yes",G66&"|"&TEXT(J66,"mmm-yyyy"),"") -> 13696|Dec-2010
A67: 541778 | B67: 77237 | C67: RED WOOLLY HOTTIE WHITE HEART | D67: 5 | E67: 40517.753 | F67: 4.25 | G67: 13247 | H67: United Kingdom | I67: =IF(AND(LEFT(OnlineRetail[[#This Row],[InvoiceNo]],1)<>"C",OnlineRetail[[#This Row],[CustomerID]]<>""),"Yes","No") -> Yes | J67: =EOMONTH(OnlineRetail[[#This Row],[InvoiceDate]],-1)+1 -> 40513 | K67: =OnlineRetail[[#This Row],[Quantity]]*OnlineRetail[[#This Row],[UnitPrice]] -> 21.25 | L67: =IF(I67="Yes",G67&"|"&TEXT(J67,"mmm-yyyy"),"") -> 13247|Dec-2010
A68: 549436 | B68: 91857 | C68: WHITE METAL LANTERN | D68: 14 | E68: 40517.807 | F68: 9.95 | G68: 14152 | H68: United Kingdom | I68: =IF(AND(LEFT(OnlineRetail[[#This Row],[InvoiceNo]],1)<>"C",OnlineRetail[[#This Row],[CustomerID]]<>""),"Yes","No") -> Yes | J68: =EOMONTH(OnlineRetail[[#This Row],[InvoiceDate]],-1)+1 -> 40513 | K68: =OnlineRetail[[#This Row],[Quantity]]*OnlineRetail[[#This Row],[UnitPrice]] -> 139.3 | L68: =IF(I68="Yes",G68&"|"&TEXT(J68,"mmm-yyyy"),"") -> 14152|Dec-2010
A69: 538214 | B69: 82450 | C69: WHITE HANGING HEART T-LIGHT HOLDER | D69: 16 | E69: 40517.81 | F69: 1.65 | G69: 13247 | H69: Germany | I69: =IF(AND(LEFT(OnlineRetail[[#This Row],[InvoiceNo]],1)<>"C",OnlineRetail[[#This Row],[CustomerID]]<>""),"Yes","No") -> Yes | J69: =EOMONTH(OnlineRetail[[#This Row],[InvoiceDate]],-1)+1 -> 40513 | K69: =OnlineRetail[[#This Row],[Quantity]]*OnlineRetail[[#This Row],[UnitPrice]] -> 26.4 | L69: =IF(I69="Yes",G69&"|"&TEXT(J69,"mmm-yyyy"),"") -> 13247|Dec-2010
A70: 551130 | B70: 91857 | C70: IVORY KNITTED MUG COSY | D70: 20 | E70: 40518.359 | F70: 0.85 | G70: 12774 | H70: United Kingdom | I70: =IF(AND(LEFT(OnlineRetail[[#This Row],[InvoiceNo]],1)<>"C",OnlineRetail[[#This Row],[CustomerID]]<>""),"Yes","No") -> Yes | J70: =EOMONTH(OnlineRetail[[#This Row],[InvoiceDate]],-1)+1 -> 40513 | K70: =OnlineRetail[[#This Row],[Quantity]]*OnlineRetail[[#This Row],[UnitPrice]] -> 17 | L70: =IF(I70="Yes",G70&"|"&TEXT(J70,"mmm-yyyy"),"") -> 12774|Dec-2010
A71: 546855 | B71: 81397 | C71: WHITE HANGING HEART T-LIGHT HOLDER | D71: 14 | E71: 40518.422 | F71: 1.65 | G71: 13706 | H71: Germany | I71: =IF(AND(LEFT(OnlineRetail[[#This Row],[InvoiceNo]],1)<>"C",OnlineRetail[[#This Row],[CustomerID]]<>""),"Yes","No") -> Yes | J71: =EOMONTH(OnlineRetail[[#This Row],[InvoiceDate]],-1)+1 -> 40513 | K71: =OnlineRetail[[#This Row],[Quantity]]*OnlineRetail[[#This Row],[UnitPrice]] -> 23.1 | L71: =IF(I71="Yes",G71&"|"&TEXT(J71,"mmm-yyyy"),"") -> 13706|Dec-2010
A72: 542903 | B72: 21043 | C72: HOME BUILDING BLOCK WORD | D72: 6 | E72: 40518.433 | F72: 4.25 | G72: 13696 | H72: Spain | I72: =IF(AND(LEFT(OnlineRetail[[#This Row],[InvoiceNo]],1)<>"C",OnlineRetail[[#This Row],[CustomerID]]<>""),"Yes","No") -> Yes | J72: =EOMONTH(OnlineRetail[[#This Row],[InvoiceDate]],-1)+1 -> 40513 | K72: =OnlineRetail[[#This Row],[Quantity]]*OnlineRetail[[#This Row],[UnitPrice]] -> 25.5 | L72: =IF(I72="Yes",G72&"|"&TEXT(J72,"mmm-yyyy"),"") -> 13696|Dec-2010
A73: 553225 | B73: 96441 | C73: RECIPE BOX WITH METAL HEART | D73: 10 | E73: 40518.436 | F73: 0.85 | G73: 12595 | H73: United Kingdom | I73: =IF(AND(LEFT(OnlineRetail[[#This Row],[InvoiceNo]],1)<>"C",OnlineRetail[[#This Row],[CustomerID]]<>""),"Yes","No") -> Yes | J73: =EOMONTH(OnlineRetail[[#This Row],[InvoiceDate]],-1)+1 -> 40513 | K73: =OnlineRetail[[#This Row],[Quantity]]*OnlineRetail[[#This Row],[UnitPrice]] -> 8.5 | L73: =IF(I73="Yes",G73&"|"&TEXT(J73,"mmm-yyyy"),"") -> 12595|Dec-2010
A74: 539101 | B74: 52341 | C74: LOVE BUILDING BLOCK WORD | D74: 22 | E74: 40518.454 | F74: 4.25 | G74: 12449 | H74: United Kingdom | I74: =IF(AND(LEFT(OnlineRetail[[#This Row],[InvoiceNo]],1)<>"C",OnlineRetail[[#This Row],[CustomerID]]<>""),"Yes","No") -> Yes | J74: =EOMONTH(OnlineRetail[[#This Row],[InvoiceDate]],-1)+1 -> 40513 | K74: =OnlineRetail[[#This Row],[Quantity]]*OnlineRetail[[#This Row],[UnitPrice]] -> 93.5 | L74: =IF(I74="Yes",G74&"|"&TEXT(J74,"mmm-yyyy"),"") -> 12449|Dec-2010
...

Sheet Customer_Month
A1: CustomerID | B1: Transaction_Month | C1: Cohort_Month | D1: Month_Number
A2: 12714 | B2: 40513 | C2: =_xlfn.MINIFS($B$2:$B$6084,$A$2:$A$6084,A2) -> 40513 | D2: =DATEDIF(C2,B2,"m") -> 0
A3: 13585 | B3: 40513 | C3: =_xlfn.MINIFS($B$2:$B$6084,$A$2:$A$6084,A3) -> 40513 | D3: =DATEDIF(C3,B3,"m") -> 0
A4: 14152 | B4: 40513 | C4: =_xlfn.MINIFS($B$2:$B$6084,$A$2:$A$6084,A4) -> 40513 | D4: =DATEDIF(C4,B4,"m") -> 0
A5: 12929 | B5: 40513 | C5: =_xlfn.MINIFS($B$2:$B$6084,$A$2:$A$6084,A5) -> 40513 | D5: =DATEDIF(C5,B5,"m") -> 0
A6: 14321 | B6: 40513 | C6: =_xlfn.MINIFS($B$2:$B$6084,$A$2:$A$6084,A6) -> 40513 | D6: =DATEDIF(C6,B6,"m") -> 0
A7: 13645 | B7: 40513 | C7: =_xlfn.MINIFS($B$2:$B$6084,$A$2:$A$6084,A7) -> 40513 | D7: =DATEDIF(C7,B7,"m") -> 0
A8: 14258 | B8: 40513 | C8: =_xlfn.MINIFS($B$2:$B$6084,$A$2:$A$6084,A8) -> 40513 | D8: =DATEDIF(C8,B8,"m") -> 0
A9: 13809 | B9: 40513 | C9: =_xlfn.MINIFS($B$2:$B$6084,$A$2:$A$6084,A9) -> 40513 | D9: =DATEDIF(C9,B9,"m") -> 0
A10: 12472 | B10: 40513 | C10: =_xlfn.MINIFS($B$2:$B$6084,$A$2:$A$6084,A10) -> 40513 | D10: =DATEDIF(C10,B10,"m") -> 0
A11: 12964 | B11: 40513 | C11: =_xlfn.MINIFS($B$2:$B$6084,$A$2:$A$6084,A11) -> 40513 | D11: =DATEDIF(C11,B11,"m") -> 0
A12: 13987 | B12: 40513 | C12: =_xlfn.MINIFS($B$2:$B$6084,$A$2:$A$6084,A12) -> 40513 | D12: =DATEDIF(C12,B12,"m") -> 0
A13: 13441 | B13: 40513 | C13: =_xlfn.MINIFS($B$2:$B$6084,$A$2:$A$6084,A13) -> 40513 | D13: =DATEDIF(C13,B13,"m") -> 0
... A6084: 13304 | B6084: 40848 | C6084: =_xlfn.MINIFS($B$2:$B$6084,$A$2:$A$6084,A6084) -> 40848 | D6084: =DATEDIF(C6084,B6084,"m") -> 0

Sheet Retention Count Matrix
A1: Cohort Month | B1: Cohort Size | C1: 0 | D1: 1 | E1: 2 | F1: 3 | G1: 4 | H1: 5 | I1: 6 | J1: 7 | K1: 8 | L1: 9 | M1: 10 | N1: 11
A2: =DATE(2010,12,1) -> 40513 | B2: =COUNTIFS(Customer_Month!$C$2:$C$6084,A2,Customer_Month!$D$2:$D$6084,0) -> 139 | C2: =COUNTIFS(Customer_Month!$C$2:$C$6084,$A2,Customer_Month!$D$2:$D$6084,C$1) -> 139 | D2: =COUNTIFS(Customer_Month!$C$2:$C$6084,$A2,Customer_Month!$D$2:$D$6084,D$1) -> 91 | E2: =COUNTIFS(Customer_Month!$C$2:$C$6084,$A2,Customer_Month!$D$2:$D$6084,E$1) -> 68 | F2: =COUNTIFS(Customer_Month!$C$2:$C$6084,$A2,Customer_Month!$D$2:$D$6084,F$1) -> 70 | G2: =COUNTIFS(Customer_Month!$C$2:$C$6084,$A2,Customer_Month!$D$2:$D$6084,G$1) -> 62 | H2: =COUNTIFS(Customer_Month!$C$2:$C$6084,$A2,Customer_Month!$D$2:$D$6084,H$1) -> 49 | I2: =COUNTIFS(Customer_Month!$C$2:$C$6084,$A2,Customer_Month!$D$2:$D$6084,I$1) -> 38 | J2: =COUNTIFS(Customer_Month!$C$2:$C$6084,$A2,Customer_Month!$D$2:$D$6084,J$1) -> 44 | ... N2: =COUNTIFS(Customer_Month!$C$2:$C$6084,$A2,Customer_Month!$D$2:$D$6084,N$1) -> 22
A3: =EDATE(A2,1) -> 40544 | B3: =COUNTIFS(Customer_Month!$C$2:$C$6084,A3,Customer_Month!$D$2:$D$6084,0) -> 192 | C3: =COUNTIFS(Customer_Month!$C$2:$C$6084,$A3,Customer_Month!$D$2:$D$6084,C$1) -> 192 | D3: =COUNTIFS(Customer_Month!$C$2:$C$6084,$A3,Customer_Month!$D$2:$D$6084,D$1) -> 119 | E3: =COUNTIFS(Customer_Month!$C$2:$C$6084,$A3,Customer_Month!$D$2:$D$6084,E$1) -> 91 | F3: =COUNTIFS(Customer_Month!$C$2:$C$6084,$A3,Customer_Month!$D$2:$D$6084,F$1) -> 80 | G3: =COUNTIFS(Customer_Month!$C$2:$C$6084,$A3,Customer_Month!$D$2:$D$6084,G$1) -> 89 | H3: =COUNTIFS(Customer_Month!$C$2:$C$6084,$A3,Customer_Month!$D$2:$D$6084,H$1) -> 68 | I3: =COUNTIFS(Customer_Month!$C$2:$C$6084,$A3,Customer_Month!$D$2:$D$6084,I$1) -> 50 | J3: =COUNTIFS(Customer_Month!$C$2:$C$6084,$A3,Customer_Month!$D$2:$D$6084,J$1) -> 46 | ... N3: =COUNTIFS(Customer_Month!$C$2:$C$6084,$A3,Customer_Month!$D$2:$D$6084,N$1) -> 0
A4: =EDATE(A3,1) -> 40575 | B4: =COUNTIFS(Customer_Month!$C$2:$C$6084,A4,Customer_Month!$D$2:$D$6084,0) -> 142 | C4: =COUNTIFS(Customer_Month!$C$2:$C$6084,$A4,Customer_Month!$D$2:$D$6084,C$1) -> 142 | D4: =COUNTIFS(Customer_Month!$C$2:$C$6084,$A4,Customer_Month!$D$2:$D$6084,D$1) -> 71 | E4: =COUNTIFS(Customer_Month!$C$2:$C$6084,$A4,Customer_Month!$D$2:$D$6084,E$1) -> 65 | F4: =COUNTIFS(Customer_Month!$C$2:$C$6084,$A4,Customer_Month!$D$2:$D$6084,F$1) -> 73 | G4: =COUNTIFS(Customer_Month!$C$2:$C$6084,$A4,Customer_Month!$D$2:$D$6084,G$1) -> 54 | H4: =COUNTIFS(Customer_Month!$C$2:$C$6084,$A4,Customer_Month!$D$2:$D$6084,H$1) -> 49 | I4: =COUNTIFS(Customer_Month!$C$2:$C$6084,$A4,Customer_Month!$D$2:$D$6084,I$1) -> 42 | J4: =COUNTIFS(Customer_Month!$C$2:$C$6084,$A4,Customer_Month!$D$2:$D$6084,J$1) -> 27 | ... N4: =COUNTIFS(Customer_Month!$C$2:$C$6084,$A4,Customer_Month!$D$2:$D$6084,N$1) -> 0
A5: =EDATE(A4,1) -> 40603 | B5: =COUNTIFS(Customer_Month!$C$2:$C$6084,A5,Customer_Month!$D$2:$D$6084,0) -> 174 | C5: =COUNTIFS(Customer_Month!$C$2:$C$6084,$A5,Customer_Month!$D$2:$D$6084,C$1) -> 174 | D5: =COUNTIFS(Customer_Month!$C$2:$C$6084,$A5,Customer_Month!$D$2:$D$6084,D$1) -> 97 | E5: =COUNTIFS(Customer_Month!$C$2:$C$6084,$A5,Customer_Month!$D$2:$D$6084,E$1) -> 78 | F5: =COUNTIFS(Customer_Month!$C$2:$C$6084,$A5,Customer_Month!$D$2:$D$6084,F$1) -> 72 | G5: =COUNTIFS(Customer_Month!$C$2:$C$6084,$A5,Customer_Month!$D$2:$D$6084,G$1) -> 65 | H5: =COUNTIFS(Customer_Month!$C$2:$C$6084,$A5,Customer_Month!$D$2:$D$6084,H$1) -> 66 | I5: =COUNTIFS(Customer_Month!$C$2:$C$6084,$A5,Customer_Month!$D$2:$D$6084,I$1) -> 46 | J5: =COUNTIFS(Customer_Month!$C$2:$C$6084,$A5,Customer_Month!$D$2:$D$6084,J$1) -> 39 | ... N5: =COUNTIFS(Customer_Month!$C$2:$C$6084,$A5,Customer_Month!$D$2:$D$6084,N$1) -> 0
A6: =EDATE(A5,1) -> 40634 | B6: =COUNTIFS(Customer_Month!$C$2:$C$6084,A6,Customer_Month!$D$2:$D$6084,0) -> 152 | C6: =COUNTIFS(Customer_Month!$C$2:$C$6084,$A6,Customer_Month!$D$2:$D$6084,C$1) -> 152 | D6: =COUNTIFS(Customer_Month!$C$2:$C$6084,$A6,Customer_Month!$D$2:$D$6084,D$1) -> 81 | E6: =COUNTIFS(Customer_Month!$C$2:$C$6084,$A6,Customer_Month!$D$2:$D$6084,E$1) -> 73 | F6: =COUNTIFS(Customer_Month!$C$2:$C$6084,$A6,Customer_Month!$D$2:$D$6084,F$1) -> 71 | G6: =COUNTIFS(Customer_Month!$C$2:$C$6084,$A6,Customer_Month!$D$2:$D$6084,G$1) -> 50 | H6: =COUNTIFS(Customer_Month!$C$2:$C$6084,$A6,Customer_Month!$D$2:$D$6084,H$1) -> 51 | I6: =COUNTIFS(Customer_Month!$C$2:$C$6084,$A6,Customer_Month!$D$2:$D$6084,I$1) -> 37 | J6: =COUNTIFS(Customer_Month!$C$2:$C$6084,$A6,Customer_Month!$D$2:$D$6084,J$1) -> 35 | ... N6: =COUNTIFS(Customer_Month!$C$2:$C$6084,$A6,Customer_Month!$D$2:$D$6084,N$1) -> 0
A7: =EDATE(A6,1) -> 40664 | B7: =COUNTIFS(Customer_Month!$C$2:$C$6084,A7,Customer_Month!$D$2:$D$6084,0) -> 166 | C7: =COUNTIFS(Customer_Month!$C$2:$C$6084,$A7,Customer_Month!$D$2:$D$6084,C$1) -> 166 | D7: =COUNTIFS(Customer_Month!$C$2:$C$6084,$A7,Customer_Month!$D$2:$D$6084,D$1) -> 96 | E7: =COUNTIFS(Customer_Month!$C$2:$C$6084,$A7,Customer_Month!$D$2:$D$6084,E$1) -> 89 | F7: =COUNTIFS(Customer_Month!$C$2:$C$6084,$A7,Customer_Month!$D$2:$D$6084,F$1) -> 70 | G7: =COUNTIFS(Customer_Month!$C$2:$C$6084,$A7,Customer_Month!$D$2:$D$6084,G$1) -> 62 | H7: =COUNTIFS(Customer_Month!$C$2:$C$6084,$A7,Customer_Month!$D$2:$D$6084,H$1) -> 57 | I7: =COUNTIFS(Customer_Month!$C$2:$C$6084,$A7,Customer_Month!$D$2:$D$6084,I$1) -> 39 | J7: =COUNTIFS(Customer_Month!$C$2:$C$6084,$A7,Customer_Month!$D$2:$D$6084,J$1) -> 0 | ... N7: =COUNTIFS(Customer_Month!$C$2:$C$6084,$A7,Customer_Month!$D$2:$D$6084,N$1) -> 0
A8: =EDATE(A7,1) -> 40695 | B8: =COUNTIFS(Customer_Month!$C$2:$C$6084,A8,Customer_Month!$D$2:$D$6084,0) -> 169 | C8: =COUNTIFS(Customer_Month!$C$2:$C$6084,$A8,Customer_Month!$D$2:$D$6084,C$1) -> 169 | D8: =COUNTIFS(Customer_Month!$C$2:$C$6084,$A8,Customer_Month!$D$2:$D$6084,D$1) -> 92 | E8: =COUNTIFS(Customer_Month!$C$2:$C$6084,$A8,Customer_Month!$D$2:$D$6084,E$1) -> 76 | F8: =COUNTIFS(Customer_Month!$C$2:$C$6084,$A8,Customer_Month!$D$2:$D$6084,F$1) -> 69 | G8: =COUNTIFS(Customer_Month!$C$2:$C$6084,$A8,Customer_Month!$D$2:$D$6084,G$1) -> 63 | H8: =COUNTIFS(Customer_Month!$C$2:$C$6084,$A8,Customer_Month!$D$2:$D$6084,H$1) -> 56 | I8: =COUNTIFS(Customer_Month!$C$2:$C$6084,$A8,Customer_Month!$D$2:$D$6084,I$1) -> 0 | J8: =COUNTIFS(Customer_Month!$C$2:$C$6084,$A8,Customer_Month!$D$2:$D$6084,J$1) -> 0 | ... N8: =COUNTIFS(Customer_Month!$C$2:$C$6084,$A8,Customer_Month!$D$2:$D$6084,N$1) -> 0
A9: =EDATE(A8,1) -> 40725 | B9: =COUNTIFS(Customer_Month!$C$2:$C$6084,A9,Customer_Month!$D$2:$D$6084,0) -> 164 | C9: =COUNTIFS(Customer_Month!$C$2:$C$6084,$A9,Customer_Month!$D$2:$D$6084,C$1) -> 164 | D9: =COUNTIFS(Customer_Month!$C$2:$C$6084,$A9,Customer_Month!$D$2:$D$6084,D$1) -> 89 | E9: =COUNTIFS(Customer_Month!$C$2:$C$6084,$A9,Customer_Month!$D$2:$D$6084,E$1) -> 84 | F9: =COUNTIFS(Customer_Month!$C$2:$C$6084,$A9,Customer_Month!$D$2:$D$6084,F$1) -> 72 | G9: =COUNTIFS(Customer_Month!$C$2:$C$6084,$A9,Customer_Month!$D$2:$D$6084,G$1) -> 61 | H9: =COUNTIFS(Customer_Month!$C$2:$C$6084,$A9,Customer_Month!$D$2:$D$6084,H$1) -> 0 | I9: =COUNTIFS(Customer_Month!$C$2:$C$6084,$A9,Customer_Month!$D$2:$D$6084,I$1) -> 0 | J9: =COUNTIFS(Customer_Month!$C$2:$C$6084,$A9,Customer_Month!$D$2:$D$6084,J$1) -> 0 | ... N9: =COUNTIFS(Customer_Month!$C$2:$C$6084,$A9,Customer_Month!$D$2:$D$6084,N$1) -> 0
A10: =EDATE(A9,1) -> 40756 | B10: =COUNTIFS(Customer_Month!$C$2:$C$6084,A10,Customer_Month!$D$2:$D$6084,0) -> 168 | C10: =COUNTIFS(Customer_Month!$C$2:$C$6084,$A10,Customer_Month!$D$2:$D$6084,C$1) -> 168 | D10: =COUNTIFS(Customer_Month!$C$2:$C$6084,$A10,Customer_Month!$D$2:$D$6084,D$1) -> 99 | E10: =COUNTIFS(Customer_Month!$C$2:$C$6084,$A10,Customer_Month!$D$2:$D$6084,E$1) -> 83 | F10: =COUNTIFS(Customer_Month!$C$2:$C$6084,$A10,Customer_Month!$D$2:$D$6084,F$1) -> 70 | G10: =COUNTIFS(Customer_Month!$C$2:$C$6084,$A10,Customer_Month!$D$2:$D$6084,G$1) -> 0 | H10: =COUNTIFS(Customer_Month!$C$2:$C$6084,$A10,Customer_Month!$D$2:$D$6084,H$1) -> 0 | I10: =COUNTIFS(Customer_Month!$C$2:$C$6084,$A10,Customer_Month!$D$2:$D$6084,I$1) -> 0 | J10: =COUNTIFS(Customer_Month!$C$2:$C$6084,$A10,Customer_Month!$D$2:$D$6084,J$1) -> 0 | ... N10: =COUNTIFS(Customer_Month!$C$2:$C$6084,$A10,Customer_Month!$D$2:$D$6084,N$1) -> 0
A11: =EDATE(A10,1) -> 40787 | B11: =COUNTIFS(Customer_Month!$C$2:$C$6084,A11,Customer_Month!$D$2:$D$6084,0) -> 162 | C11: =COUNTIFS(Customer_Month!$C$2:$C$6084,$A11,Customer_Month!$D$2:$D$6084,C$1) -> 162 | D11: =COUNTIFS(Customer_Month!$C$2:$C$6084,$A11,Customer_Month!$D$2:$D$6084,D$1) -> 80 | E11: =COUNTIFS(Customer_Month!$C$2:$C$6084,$A11,Customer_Month!$D$2:$D$6084,E$1) -> 85 | F11: =COUNTIFS(Customer_Month!$C$2:$C$6084,$A11,Customer_Month!$D$2:$D$6084,F$1) -> 0 | G11: =COUNTIFS(Customer_Month!$C$2:$C$6084,$A11,Customer_Month!$D$2:$D$6084,G$1) -> 0 | H11: =COUNTIFS(Customer_Month!$C$2:$C$6084,$A11,Customer_Month!$D$2:$D$6084,H$1) -> 0 | I11: =COUNTIFS(Customer_Month!$C$2:$C$6084,$A11,Customer_Month!$D$2:$D$6084,I$1) -> 0 | J11: =COUNTIFS(Customer_Month!$C$2:$C$6084,$A11,Customer_Month!$D$2:$D$6084,J$1) -> 0 | ... N11: =COUNTIFS(Customer_Month!$C$2:$C$6084,$A11,Customer_Month!$D$2:$D$6084,N$1) -> 0
A12: =EDATE(A11,1) -> 40817 | B12: =COUNTIFS(Customer_Month!$C$2:$C$6084,A12,Customer_Month!$D$2:$D$6084,0) -> 164 | C12: =COUNTIFS(Customer_Month!$C$2:$C$6084,$A12,Customer_Month!$D$2:$D$6084,C$1) -> 164 | D12: =COUNTIFS(Customer_Month!$C$2:$C$6084,$A12,Customer_Month!$D$2:$D$6084,D$1) -> 88 | E12: =COUNTIFS(Customer_Month!$C$2:$C$6084,$A12,Customer_Month!$D$2:$D$6084,E$1) -> 0 | F12: =COUNTIFS(Customer_Month!$C$2:$C$6084,$A12,Customer_Month!$D$2:$D$6084,F$1) -> 0 | G12: =COUNTIFS(Customer_Month!$C$2:$C$6084,$A12,Customer_Month!$D$2:$D$6084,G$1) -> 0 | H12: =COUNTIFS(Customer_Month!$C$2:$C$6084,$A12,Customer_Month!$D$2:$D$6084,H$1) -> 0 | I12: =COUNTIFS(Customer_Month!$C$2:$C$6084,$A12,Customer_Month!$D$2:$D$6084,I$1) -> 0 | J12: =COUNTIFS(Customer_Month!$C$2:$C$6084,$A12,Customer_Month!$D$2:$D$6084,J$1) -> 0 | ... N12: =COUNTIFS(Customer_Month!$C$2:$C$6084,$A12,Customer_Month!$D$2:$D$6084,N$1) -> 0
A13: =EDATE(A12,1) -> 40848 | B13: =COUNTIFS(Customer_Month!$C$2:$C$6084,A13,Customer_Month!$D$2:$D$6084,0) -> 176 | C13: =COUNTIFS(Customer_Month!$C$2:$C$6084,$A13,Customer_Month!$D$2:$D$6084,C$1) -> 176 | D13: =COUNTIFS(Customer_Month!$C$2:$C$6084,$A13,Customer_Month!$D$2:$D$6084,D$1) -> 0 | E13: =COUNTIFS(Customer_Month!$C$2:$C$6084,$A13,Customer_Month!$D$2:$D$6084,E$1) -> 0 | F13: =COUNTIFS(Customer_Month!$C$2:$C$6084,$A13,Customer_Month!$D$2:$D$6084,F$1) -> 0 | G13: =COUNTIFS(Customer_Month!$C$2:$C$6084,$A13,Customer_Month!$D$2:$D$6084,G$1) -> 0 | H13: =COUNTIFS(Customer_Month!$C$2:$C$6084,$A13,Customer_Month!$D$2:$D$6084,H$1) -> 0 | I13: =COUNTIFS(Customer_Month!$C$2:$C$6084,$A13,Customer_Month!$D$2:$D$6084,I$1) -> 0 | J13: =COUNTIFS(Customer_Month!$C$2:$C$6084,$A13,Customer_Month!$D$2:$D$6084,J$1) -> 0 | ... N13: =COUNTIFS(Customer_Month!$C$2:$C$6084,$A13,Customer_Month!$D$2:$D$6084,N$1) -> 0

Sheet KPI_Calculations
A1: Cohort Retention KPIs | D1: Retention Trend Data | G1: Cohort Size Trend Data
A3: Total Customers | B3: =SUM(Dashboard!$B$13:$B$24) -> 1968 | D3: Month | E3: Average Retention | G3: Cohort Month | H3: Cohort Size | J3: Dec-2010 Retention | K3: Retention
A4: Total Cohorts | B4: =COUNTA(Dashboard!$A$13:$A$24) -> 12 | D4: ="Month "&ROWS($D$4:D4)-1 -> Month 0 | E4: =AVERAGE(INDEX(Dashboard!$C$13:$N$24,0,ROWS($D$4:D4))) -> 1 | G4: =Dashboard!A13 -> 40513 | H4: =Dashboard!B13 -> 139 | J4: ="Month "&ROW()-4 -> Month 0 | K4: =INDEX(Dashboard!$C$13:$N$13,1,ROWS($K$4:K4)) -> 1
A5: Average Cohort Size | B5: =AVERAGE(Dashboard!$B$13:$B$24) -> 164 | D5: ="Month "&ROWS($D$4:D5)-1 -> Month 1 | E5: =AVERAGE(INDEX(Dashboard!$C$13:$N$24,0,ROWS($D$4:D5))) -> 0.55908246 | G5: =Dashboard!A14 -> 40544 | H5: =Dashboard!B14 -> 192 | J5: ="Month "&ROW()-4 -> Month 1 | K5: =INDEX(Dashboard!$C$13:$N$13,1,ROWS($K$4:K5)) -> 0.65467626
A6: Average Month 1 Retention | B6: =AVERAGE(Dashboard!$D$13:$D$24) -> 0.55908246 | D6: ="Month "&ROWS($D$4:D6)-1 -> Month 2 | E6: =AVERAGE(INDEX(Dashboard!$C$13:$N$24,0,ROWS($D$4:D6))) -> 0.48662353 | G6: =Dashboard!A15 -> 40575 | H6: =Dashboard!B15 -> 142 | J6: ="Month "&ROW()-4 -> Month 2 | K6: =INDEX(Dashboard!$C$13:$N$13,1,ROWS($K$4:K6)) -> 0.48920863
A7: Average Month 3 Retention | B7: =AVERAGE(Dashboard!$F$13:$F$24) -> 0.44454539 | D7: ="Month "&ROWS($D$4:D7)-1 -> Month 3 | E7: =AVERAGE(INDEX(Dashboard!$C$13:$N$24,0,ROWS($D$4:D7))) -> 0.44454539 | G7: =Dashboard!A16 -> 40603 | H7: =Dashboard!B16 -> 174 | J7: ="Month "&ROW()-4 -> Month 3 | K7: =INDEX(Dashboard!$C$13:$N$13,1,ROWS($K$4:K7)) -> 0.50359712
A8: Average Month 6 Retention | B8: =AVERAGE(Dashboard!$I$13:$I$24) -> 0.26205021 | D8: ="Month "&ROWS($D$4:D8)-1 -> Month 4 | E8: =AVERAGE(INDEX(Dashboard!$C$13:$N$24,0,ROWS($D$4:D8))) -> 0.38882542 | G8: =Dashboard!A17 -> 40634 | H8: =Dashboard!B17 -> 152 | J8: ="Month "&ROW()-4 -> Month 4 | K8: =INDEX(Dashboard!$C$13:$N$13,1,ROWS($K$4:K8)) -> 0.44604317
D9: ="Month "&ROWS($D$4:D9)-1 -> Month 5 | E9: =AVERAGE(INDEX(Dashboard!$C$13:$N$24,0,ROWS($D$4:D9))) -> 0.34876088 | G9: =Dashboard!A18 -> 40664 | H9: =Dashboard!B18 -> 166 | J9: ="Month "&ROW()-4 -> Month 5 | K9: =INDEX(Dashboard!$C$13:$N$13,1,ROWS($K$4:K9)) -> 0.35251799
D10: ="Month "&ROWS($D$4:D10)-1 -> Month 6 | E10: =AVERAGE(INDEX(Dashboard!$C$13:$N$24,0,ROWS($D$4:D10))) -> 0.26205021 | G10: =Dashboard!A19 -> 40695 | H10: =Dashboard!B19 -> 169 | J10: ="Month "&ROW()-4 -> Month 6 | K10: =INDEX(Dashboard!$C$13:$N$13,1,ROWS($K$4:K10)) -> 0.27338129
D11: ="Month "&ROWS($D$4:D11)-1 -> Month 7 | E11: =AVERAGE(INDEX(Dashboard!$C$13:$N$24,0,ROWS($D$4:D11))) -> 0.24013441 | G11: =Dashboard!A20 -> 40725 | H11: =Dashboard!B20 -> 164 | J11: ="Month "&ROW()-4 -> Month 7 | K11: =INDEX(Dashboard!$C$13:$N$13,1,ROWS($K$4:K11)) -> 0.31654676
D12: ="Month "&ROWS($D$4:D12)-1 -> Month 8 | E12: =AVERAGE(INDEX(Dashboard!$C$13:$N$24,0,ROWS($D$4:D12))) -> 0.22718278 | G12: =Dashboard!A21 -> 40756 | H12: =Dashboard!B21 -> 168 | J12: ="Month "&ROW()-4 -> Month 8 | K12: =INDEX(Dashboard!$C$13:$N$13,1,ROWS($K$4:K12)) -> 0.23741007
D13: ="Month "&ROWS($D$4:D13)-1 -> Month 9 | E13: =AVERAGE(INDEX(Dashboard!$C$13:$N$24,0,ROWS($D$4:D13))) -> 0.21747021 | G13: =Dashboard!A22 -> 40787 | H13: =Dashboard!B22 -> 162 | J13: ="Month "&ROW()-4 -> Month 9 | K13: =INDEX(Dashboard!$C$13:$N$13,1,ROWS($K$4:K13)) -> 0.26618705
D14: ="Month "&ROWS($D$4:D14)-1 -> Month 10 | E14: =AVERAGE(INDEX(Dashboard!$C$13:$N$24,0,ROWS($D$4:D14))) -> 0.17363609 | G14: =Dashboard!A23 -> 40817 | H14: =Dashboard!B23 -> 164 | J14: ="Month "&ROW()-4 -> Month 10 | K14: =INDEX(Dashboard!$C$13:$N$13,1,ROWS($K$4:K14)) -> 0.20143885
D15: ="Month "&ROWS($D$4:D15)-1 -> Month 11 | E15: =AVERAGE(INDEX(Dashboard!$C$13:$N$24,0,ROWS($D$4:D15))) -> 0.15827338 | G15: =Dashboard!A24 -> 40848 | H15: =Dashboard!B24 -> 176 | J15: ="Month "&ROW()-4 -> Month 11 | K15: =INDEX(Dashboard!$C$13:$N$13,1,ROWS($K$4:K15)) -> 0.15827338

Sheet Dashboard
A1: CUSTOMER COHORT RETENTION DASHBOARD
A3: Online Retail | Monthly Customer Lifecycle & Retention Analysis
A5: TOTAL CUSTOMERS | D5: TOTAL COHORTS | G5: AVG COHORT SIZE | J5: MONTH 1 RETENTION | M5: MONTH 3 RETENTION | P5: MONTH 6 RETENTION
A6: =KPI_Calculations!B3 -> 1968 | D6: =KPI_Calculations!B4 -> 12 | G6: =KPI_Calculations!B5 -> 164 | J6: =KPI_Calculations!B6 -> 0.55908246 | M6: =KPI_Calculations!B7 -> 0.44454539 | P6: =KPI_Calculations!B8 -> 0.26205021
A9: COHORT RETENTION (%)
A10: Retention rate by customer acquisition cohort and months since first purchase
A12: Cohort Month | B12: Cohort Size | C12: 0 | D12: 1 | E12: 2 | F12: 3 | G12: 4 | H12: 5 | I12: 6 | J12: 7 | K12: 8 | L12: 9 | M12: 10 | N12: 11
A13: ='Retention Count Matrix'!A2 -> 40513 | B13: ='Retention Count Matrix'!B2 -> 139 | C13: =IF(EDATE($A13,C$12)>MAX(Customer_Month!$B:$B),"",IFERROR('Retention Count Matrix'!C2/'Retention Count Matrix'!$B2,"")) -> 1 | D13: =IF(EDATE($A13,D$12)>MAX(Customer_Month!$B:$B),"",IFERROR('Retention Count Matrix'!D2/'Retention Count Matrix'!$B2,"")) -> 0.65467626 | E13: =IF(EDATE($A13,E$12)>MAX(Customer_Month!$B:$B),"",IFERROR('Retention Count Matrix'!E2/'Retention Count Matrix'!$B2,"")) -> 0.48920863 | F13: =IF(EDATE($A13,F$12)>MAX(Customer_Month!$B:$B),"",IFERROR('Retention Count Matrix'!F2/'Retention Count Matrix'!$B2,"")) -> 0.50359712 | G13: =IF(EDATE($A13,G$12)>MAX(Customer_Month!$B:$B),"",IFERROR('Retention Count Matrix'!G2/'Retention Count Matrix'!$B2,"")) -> 0.44604317 | H13: =IF(EDATE($A13,H$12)>MAX(Customer_Month!$B:$B),"",IFERROR('Retention Count Matrix'!H2/'Retention Count Matrix'!$B2,"")) -> 0.35251799 | I13: =IF(EDATE($A13,I$12)>MAX(Customer_Month!$B:$B),"",IFERROR('Retention Count Matrix'!I2/'Retention Count Matrix'!$B2,"")) -> 0.27338129 | J13: =IF(EDATE($A13,J$12)>MAX(Customer_Month!$B:$B),"",IFERROR('Retention Count Matrix'!J2/'Retention Count Matrix'!$B2,"")) -> 0.31654676 | ... N13: =IF(EDATE($A13,N$12)>MAX(Customer_Month!$B:$B),"",IFERROR('Retention Count Matrix'!N2/'Retention Count Matrix'!$B2,"")) -> 0.15827338 | P13: HOW TO READ
A14: ='Retention Count Matrix'!A3 -> 40544 | B14: ='Retention Count Matrix'!B3 -> 192 | C14: =IFERROR('Retention Count Matrix'!C3/'Retention Count Matrix'!$B3,"") -> 1 | D14: =IF(EDATE($A14,D$12)>MAX(Customer_Month!$B:$B),"",IFERROR('Retention Count Matrix'!D3/'Retention Count Matrix'!$B3,"")) -> 0.61979167 | E14: =IF(EDATE($A14,E$12)>MAX(Customer_Month!$B:$B),"",IFERROR('Retention Count Matrix'!E3/'Retention Count Matrix'!$B3,"")) -> 0.47395833 | F14: =IF(EDATE($A14,F$12)>MAX(Customer_Month!$B:$B),"",IFERROR('Retention Count Matrix'!F3/'Retention Count Matrix'!$B3,"")) -> 0.41666667 | G14: =IF(EDATE($A14,G$12)>MAX(Customer_Month!$B:$B),"",IFERROR('Retention Count Matrix'!G3/'Retention Count Matrix'!$B3,"")) -> 0.46354167 | H14: =IF(EDATE($A14,H$12)>MAX(Customer_Month!$B:$B),"",IFERROR('Retention Count Matrix'!H3/'Retention Count Matrix'!$B3,"")) -> 0.35416667 | I14: =IF(EDATE($A14,I$12)>MAX(Customer_Month!$B:$B),"",IFERROR('Retention Count Matrix'!I3/'Retention Count Matrix'!$B3,"")) -> 0.26041667 | J14: =IF(EDATE($A14,J$12)>MAX(Customer_Month!$B:$B),"",IFERROR('Retention Count Matrix'!J3/'Retention Count Matrix'!$B3,"")) -> 0.23958333 | K14: =IF(EDATE($A14,K$12)>MAX(Customer_Month!$B:$B),"",IFERROR('Retention Count Matrix'!K3/'Retention Count Matrix'!$B3,"")) -> 0.25 | ... N14: =IF(EDATE($A14,N$12)>MAX(Customer_Month!$B:$B),"",IFERROR('Retention Count Matrix'!N3/'Retention Count Matrix'!$B3,"")) | P14: • Each row represents a customer acquisition cohort.
A15: ='Retention Count Matrix'!A4 -> 40575 | B15: ='Retention Count Matrix'!B4 -> 142 | C15: =IFERROR('Retention Count Matrix'!C4/'Retention Count Matrix'!$B4,"") -> 1 | D15: =IF(EDATE($A15,D$12)>MAX(Customer_Month!$B:$B),"",IFERROR('Retention Count Matrix'!D4/'Retention Count Matrix'!$B4,"")) -> 0.5 | E15: =IF(EDATE($A15,E$12)>MAX(Customer_Month!$B:$B),"",IFERROR('Retention Count Matrix'!E4/'Retention Count Matrix'!$B4,"")) -> 0.45774648 | F15: =IF(EDATE($A15,F$12)>MAX(Customer_Month!$B:$B),"",IFERROR('Retention Count Matrix'!F4/'Retention Count Matrix'!$B4,"")) -> 0.51408451 | G15: =IF(EDATE($A15,G$12)>MAX(Customer_Month!$B:$B),"",IFERROR('Retention Count Matrix'!G4/'Retention Count Matrix'!$B4,"")) -> 0.38028169 | H15: =IF(EDATE($A15,H$12)>MAX(Customer_Month!$B:$B),"",IFERROR('Retention Count Matrix'!H4/'Retention Count Matrix'!$B4,"")) -> 0.34507042 | I15: =IF(EDATE($A15,I$12)>MAX(Customer_Month!$B:$B),"",IFERROR('Retention Count Matrix'!I4/'Retention Count Matrix'!$B4,"")) -> 0.29577465 | J15: =IF(EDATE($A15,J$12)>MAX(Customer_Month!$B:$B),"",IFERROR('Retention Count Matrix'!J4/'Retention Count Matrix'!$B4,"")) -> 0.19014085 | K15: =IF(EDATE($A15,K$12)>MAX(Customer_Month!$B:$B),"",IFERROR('Retention Count Matrix'!K4/'Retention Count Matrix'!$B4,"")) -> 0.1971831 | ... N15: =IF(EDATE($A15,N$12)>MAX(Customer_Month!$B:$B),"",IFERROR('Retention Count Matrix'!N4/'Retention Count Matrix'!$B4,""))
A16: ='Retention Count Matrix'!A5 -> 40603 | B16: ='Retention Count Matrix'!B5 -> 174 | C16: =IFERROR('Retention Count Matrix'!C5/'Retention Count Matrix'!$B5,"") -> 1 | D16: =IF(EDATE($A16,D$12)>MAX(Customer_Month!$B:$B),"",IFERROR('Retention Count Matrix'!D5/'Retention Count Matrix'!$B5,"")) -> 0.55747126 | E16: =IF(EDATE($A16,E$12)>MAX(Customer_Month!$B:$B),"",IFERROR('Retention Count Matrix'!E5/'Retention Count Matrix'!$B5,"")) -> 0.44827586 | F16: =IF(EDATE($A16,F$12)>MAX(Customer_Month!$B:$B),"",IFERROR('Retention Count Matrix'!F5/'Retention Count Matrix'!$B5,"")) -> 0.4137931 | G16: =IF(EDATE($A16,G$12)>MAX(Customer_Month!$B:$B),"",IFERROR('Retention Count Matrix'!G5/'Retention Count Matrix'!$B5,"")) -> 0.37356322 | H16: =IF(EDATE($A16,H$12)>MAX(Customer_Month!$B:$B),"",IFERROR('Retention Count Matrix'!H5/'Retention Count Matrix'!$B5,"")) -> 0.37931034 | I16: =IF(EDATE($A16,I$12)>MAX(Customer_Month!$B:$B),"",IFERROR('Retention Count Matrix'!I5/'Retention Count Matrix'!$B5,"")) -> 0.26436782 | J16: =IF(EDATE($A16,J$12)>MAX(Customer_Month!$B:$B),"",IFERROR('Retention Count Matrix'!J5/'Retention Count Matrix'!$B5,"")) -> 0.22413793 | K16: =IF(EDATE($A16,K$12)>MAX(Customer_Month!$B:$B),"",IFERROR('Retention Count Matrix'!K5/'Retention Count Matrix'!$B5,"")) -> 0.22413793 | ... N16: =IF(EDATE($A16,N$12)>MAX(Customer_Month!$B:$B),"",IFERROR('Retention Count Matrix'!N5/'Retention Count Matrix'!$B5,"")) | P16: • Month 0 is the customer's first purchase month.
A17: ='Retention Count Matrix'!A6 -> 40634 | B17: ='Retention Count Matrix'!B6 -> 152 | C17: =IFERROR('Retention Count Matrix'!C6/'Retention Count Matrix'!$B6,"") -> 1 | D17: =IF(EDATE($A17,D$12)>MAX(Customer_Month!$B:$B),"",IFERROR('Retention Count Matrix'!D6/'Retention Count Matrix'!$B6,"")) -> 0.53289474 | E17: =IF(EDATE($A17,E$12)>MAX(Customer_Month!$B:$B),"",IFERROR('Retention Count Matrix'!E6/'Retention Count Matrix'!$B6,"")) -> 0.48026316 | F17: =IF(EDATE($A17,F$12)>MAX(Customer_Month!$B:$B),"",IFERROR('Retention Count Matrix'!F6/'Retention Count Matrix'!$B6,"")) -> 0.46710526 | G17: =IF(EDATE($A17,G$12)>MAX(Customer_Month!$B:$B),"",IFERROR('Retention Count Matrix'!G6/'Retention Count Matrix'!$B6,"")) -> 0.32894737 | H17: =IF(EDATE($A17,H$12)>MAX(Customer_Month!$B:$B),"",IFERROR('Retention Count Matrix'!H6/'Retention Count Matrix'!$B6,"")) -> 0.33552632 | I17: =IF(EDATE($A17,I$12)>MAX(Customer_Month!$B:$B),"",IFERROR('Retention Count Matrix'!I6/'Retention Count Matrix'!$B6,"")) -> 0.24342105 | J17: =IF(EDATE($A17,J$12)>MAX(Customer_Month!$B:$B),"",IFERROR('Retention Count Matrix'!J6/'Retention Count Matrix'!$B6,"")) -> 0.23026316 | K17: =IF(EDATE($A17,K$12)>MAX(Customer_Month!$B:$B),"",IFERROR('Retention Count Matrix'!K6/'Retention Count Matrix'!$B6,"")) | ... N17: =IF(EDATE($A17,N$12)>MAX(Customer_Month!$B:$B),"",IFERROR('Retention Count Matrix'!N6/'Retention Count Matrix'!$B6,""))
A18: ='Retention Count Matrix'!A7 -> 40664 | B18: ='Retention Count Matrix'!B7 -> 166 | C18: =IFERROR('Retention Count Matrix'!C7/'Retention Count Matrix'!$B7,"") -> 1 | D18: =IF(EDATE($A18,D$12)>MAX(Customer_Month!$B:$B),"",IFERROR('Retention Count Matrix'!D7/'Retention Count Matrix'!$B7,"")) -> 0.57831325 | E18: =IF(EDATE($A18,E$12)>MAX(Customer_Month!$B:$B),"",IFERROR('Retention Count Matrix'!E7/'Retention Count Matrix'!$B7,"")) -> 0.53614458 | F18: =IF(EDATE($A18,F$12)>MAX(Customer_Month!$B:$B),"",IFERROR('Retention Count Matrix'!F7/'Retention Count Matrix'!$B7,"")) -> 0.42168675 | G18: =IF(EDATE($A18,G$12)>MAX(Customer_Month!$B:$B),"",IFERROR('Retention Count Matrix'!G7/'Retention Count Matrix'!$B7,"")) -> 0.37349398 | H18: =IF(EDATE($A18,H$12)>MAX(Customer_Month!$B:$B),"",IFERROR('Retention Count Matrix'!H7/'Retention Count Matrix'!$B7,"")) -> 0.34337349 | I18: =IF(EDATE($A18,I$12)>MAX(Customer_Month!$B:$B),"",IFERROR('Retention Count Matrix'!I7/'Retention Count Matrix'!$B7,"")) -> 0.23493976 | J18: =IF(EDATE($A18,J$12)>MAX(Customer_Month!$B:$B),"",IFERROR('Retention Count Matrix'!J7/'Retention Count Matrix'!$B7,"")) | K18: =IF(EDATE($A18,K$12)>MAX(Customer_Month!$B:$B),"",IFERROR('Retention Count Matrix'!K7/'Retention Count Matrix'!$B7,"")) | ... N18: =IF(EDATE($A18,N$12)>MAX(Customer_Month!$B:$B),"",IFERROR('Retention Count Matrix'!N7/'Retention Count Matrix'!$B7,"")) | P18: • Percentages show the share of the cohort that returned.
A19: ='Retention Count Matrix'!A8 -> 40695 | B19: ='Retention Count Matrix'!B8 -> 169 | C19: =IFERROR('Retention Count Matrix'!C8/'Retention Count Matrix'!$B8,"") -> 1 | D19: =IF(EDATE($A19,D$12)>MAX(Customer_Month!$B:$B),"",IFERROR('Retention Count Matrix'!D8/'Retention Count Matrix'!$B8,"")) -> 0.5443787 | E19: =IF(EDATE($A19,E$12)>MAX(Customer_Month!$B:$B),"",IFERROR('Retention Count Matrix'!E8/'Retention Count Matrix'!$B8,"")) -> 0.44970414 | F19: =IF(EDATE($A19,F$12)>MAX(Customer_Month!$B:$B),"",IFERROR('Retention Count Matrix'!F8/'Retention Count Matrix'!$B8,"")) -> 0.40828402 | G19: =IF(EDATE($A19,G$12)>MAX(Customer_Month!$B:$B),"",IFERROR('Retention Count Matrix'!G8/'Retention Count Matrix'!$B8,"")) -> 0.37278107 | H19: =IF(EDATE($A19,H$12)>MAX(Customer_Month!$B:$B),"",IFERROR('Retention Count Matrix'!H8/'Retention Count Matrix'!$B8,"")) -> 0.33136095 | I19: =IF(EDATE($A19,I$12)>MAX(Customer_Month!$B:$B),"",IFERROR('Retention Count Matrix'!I8/'Retention Count Matrix'!$B8,"")) | J19: =IF(EDATE($A19,J$12)>MAX(Customer_Month!$B:$B),"",IFERROR('Retention Count Matrix'!J8/'Retention Count Matrix'!$B8,"")) | K19: =IF(EDATE($A19,K$12)>MAX(Customer_Month!$B:$B),"",IFERROR('Retention Count Matrix'!K8/'Retention Count Matrix'!$B8,"")) | ... N19: =IF(EDATE($A19,N$12)>MAX(Customer_Month!$B:$B),"",IFERROR('Retention Count Matrix'!N8/'Retention Count Matrix'!$B8,""))
A20: ='Retention Count Matrix'!A9 -> 40725 | B20: ='Retention Count Matrix'!B9 -> 164 | C20: =IFERROR('Retention Count Matrix'!C9/'Retention Count Matrix'!$B9,"") -> 1 | D20: =IF(EDATE($A20,D$12)>MAX(Customer_Month!$B:$B),"",IFERROR('Retention Count Matrix'!D9/'Retention Count Matrix'!$B9,"")) -> 0.54268293 | E20: =IF(EDATE($A20,E$12)>MAX(Customer_Month!$B:$B),"",IFERROR('Retention Count Matrix'!E9/'Retention Count Matrix'!$B9,"")) -> 0.51219512 | F20: =IF(EDATE($A20,F$12)>MAX(Customer_Month!$B:$B),"",IFERROR('Retention Count Matrix'!F9/'Retention Count Matrix'!$B9,"")) -> 0.43902439 | G20: =IF(EDATE($A20,G$12)>MAX(Customer_Month!$B:$B),"",IFERROR('Retention Count Matrix'!G9/'Retention Count Matrix'!$B9,"")) -> 0.37195122 | H20: =IF(EDATE($A20,H$12)>MAX(Customer_Month!$B:$B),"",IFERROR('Retention Count Matrix'!H9/'Retention Count Matrix'!$B9,"")) | I20: =IF(EDATE($A20,I$12)>MAX(Customer_Month!$B:$B),"",IFERROR('Retention Count Matrix'!I9/'Retention Count Matrix'!$B9,"")) | J20: =IF(EDATE($A20,J$12)>MAX(Customer_Month!$B:$B),"",IFERROR('Retention Count Matrix'!J9/'Retention Count Matrix'!$B9,"")) | K20: =IF(EDATE($A20,K$12)>MAX(Customer_Month!$B:$B),"",IFERROR('Retention Count Matrix'!K9/'Retention Count Matrix'!$B9,"")) | ... N20: =IF(EDATE($A20,N$12)>MAX(Customer_Month!$B:$B),"",IFERROR('Retention Count Matrix'!N9/'Retention Count Matrix'!$B9,"")) | P20: • Darker green indicates stronger retention.
A21: ='Retention Count Matrix'!A10 -> 40756 | B21: ='Retention Count Matrix'!B10 -> 168 | C21: =IFERROR('Retention Count Matrix'!C10/'Retention Count Matrix'!$B10,"") -> 1 | D21: =IF(EDATE($A21,D$12)>MAX(Customer_Month!$B:$B),"",IFERROR('Retention Count Matrix'!D10/'Retention Count Matrix'!$B10,"")) -> 0.58928571 | E21: =IF(EDATE($A21,E$12)>MAX(Customer_Month!$B:$B),"",IFERROR('Retention Count Matrix'!E10/'Retention Count Matrix'!$B10,"")) -> 0.49404762 | F21: =IF(EDATE($A21,F$12)>MAX(Customer_Month!$B:$B),"",IFERROR('Retention Count Matrix'!F10/'Retention Count Matrix'!$B10,"")) -> 0.41666667 | G21: =IF(EDATE($A21,G$12)>MAX(Customer_Month!$B:$B),"",IFERROR('Retention Count Matrix'!G10/'Retention Count Matrix'!$B10,"")) | H21: =IF(EDATE($A21,H$12)>MAX(Customer_Month!$B:$B),"",IFERROR('Retention Count Matrix'!H10/'Retention Count Matrix'!$B10,"")) | I21: =IF(EDATE($A21,I$12)>MAX(Customer_Month!$B:$B),"",IFERROR('Retention Count Matrix'!I10/'Retention Count Matrix'!$B10,"")) | J21: =IF(EDATE($A21,J$12)>MAX(Customer_Month!$B:$B),"",IFERROR('Retention Count Matrix'!J10/'Retention Count Matrix'!$B10,"")) | K21: =IF(EDATE($A21,K$12)>MAX(Customer_Month!$B:$B),"",IFERROR('Retention Count Matrix'!K10/'Retention Count Matrix'!$B10,"")) | ... N21: =IF(EDATE($A21,N$12)>MAX(Customer_Month!$B:$B),"",IFERROR('Retention Count Matrix'!N10/'Retention Count Matrix'!$B10,""))
A22: ='Retention Count Matrix'!A11 -> 40787 | B22: ='Retention Count Matrix'!B11 -> 162 | C22: =IFERROR('Retention Count Matrix'!C11/'Retention Count Matrix'!$B11,"") -> 1 | D22: =IF(EDATE($A22,D$12)>MAX(Customer_Month!$B:$B),"",IFERROR('Retention Count Matrix'!D11/'Retention Count Matrix'!$B11,"")) -> 0.49382716 | E22: =IF(EDATE($A22,E$12)>MAX(Customer_Month!$B:$B),"",IFERROR('Retention Count Matrix'!E11/'Retention Count Matrix'!$B11,"")) -> 0.52469136 | F22: =IF(EDATE($A22,F$12)>MAX(Customer_Month!$B:$B),"",IFERROR('Retention Count Matrix'!F11/'Retention Count Matrix'!$B11,"")) | G22: =IF(EDATE($A22,G$12)>MAX(Customer_Month!$B:$B),"",IFERROR('Retention Count Matrix'!G11/'Retention Count Matrix'!$B11,"")) | H22: =IF(EDATE($A22,H$12)>MAX(Customer_Month!$B:$B),"",IFERROR('Retention Count Matrix'!H11/'Retention Count Matrix'!$B11,"")) | I22: =IF(EDATE($A22,I$12)>MAX(Customer_Month!$B:$B),"",IFERROR('Retention Count Matrix'!I11/'Retention Count Matrix'!$B11,"")) | J22: =IF(EDATE($A22,J$12)>MAX(Customer_Month!$B:$B),"",IFERROR('Retention Count Matrix'!J11/'Retention Count Matrix'!$B11,"")) | K22: =IF(EDATE($A22,K$12)>MAX(Customer_Month!$B:$B),"",IFERROR('Retention Count Matrix'!K11/'Retention Count Matrix'!$B11,"")) | ... N22: =IF(EDATE($A22,N$12)>MAX(Customer_Month!$B:$B),"",IFERROR('Retention Count Matrix'!N11/'Retention Count Matrix'!$B11,"")) | P22: • Blank cells represent months not yet observable.
A23: ='Retention Count Matrix'!A12 -> 40817 | B23: ='Retention Count Matrix'!B12 -> 164 | C23: =IFERROR('Retention Count Matrix'!C12/'Retention Count Matrix'!$B12,"") -> 1 | D23: =IF(EDATE($A23,D$12)>MAX(Customer_Month!$B:$B),"",IFERROR('Retention Count Matrix'!D12/'Retention Count Matrix'!$B12,"")) -> 0.53658537 | E23: =IF(EDATE($A23,E$12)>MAX(Customer_Month!$B:$B),"",IFERROR('Retention Count Matrix'!E12/'Retention Count Matrix'!$B12,"")) | F23: =IF(EDATE($A23,F$12)>MAX(Customer_Month!$B:$B),"",IFERROR('Retention Count Matrix'!F12/'Retention Count Matrix'!$B12,"")) | G23: =IF(EDATE($A23,G$12)>MAX(Customer_Month!$B:$B),"",IFERROR('Retention Count Matrix'!G12/'Retention Count Matrix'!$B12,"")) | H23: =IF(EDATE($A23,H$12)>MAX(Customer_Month!$B:$B),"",IFERROR('Retention Count Matrix'!H12/'Retention Count Matrix'!$B12,"")) | I23: =IF(EDATE($A23,I$12)>MAX(Customer_Month!$B:$B),"",IFERROR('Retention Count Matrix'!I12/'Retention Count Matrix'!$B12,"")) | J23: =IF(EDATE($A23,J$12)>MAX(Customer_Month!$B:$B),"",IFERROR('Retention Count Matrix'!J12/'Retention Count Matrix'!$B12,"")) | K23: =IF(EDATE($A23,K$12)>MAX(Customer_Month!$B:$B),"",IFERROR('Retention Count Matrix'!K12/'Retention Count Matrix'!$B12,"")) | ... N23: =IF(EDATE($A23,N$12)>MAX(Customer_Month!$B:$B),"",IFERROR('Retention Count Matrix'!N12/'Retention Count Matrix'!$B12,""))
A24: ='Retention Count Matrix'!A13 -> 40848 | B24: ='Retention Count Matrix'!B13 -> 176 | C24: =IFERROR('Retention Count Matrix'!C13/'Retention Count Matrix'!$B13,"") -> 1 | D24: =IF(EDATE($A24,D$12)>MAX(Customer_Month!$B:$B),"",IFERROR('Retention Count Matrix'!D13/'Retention Count Matrix'!$B13,"")) | E24: =IF(EDATE($A24,E$12)>MAX(Customer_Month!$B:$B),"",IFERROR('Retention Count Matrix'!E13/'Retention Count Matrix'!$B13,"")) | F24: =IF(EDATE($A24,F$12)>MAX(Customer_Month!$B:$B),"",IFERROR('Retention Count Matrix'!F13/'Retention Count Matrix'!$B13,"")) | G24: =IF(EDATE($A24,G$12)>MAX(Customer_Month!$B:$B),"",IFERROR('Retention Count Matrix'!G13/'Retention Count Matrix'!$B13,"")) | H24: =IF(EDATE($A24,H$12)>MAX(Customer_Month!$B:$B),"",IFERROR('Retention Count Matrix'!H13/'Retention Count Matrix'!$B13,"")) | I24: =IF(EDATE($A24,I$12)>MAX(Customer_Month!$B:$B),"",IFERROR('Retention Count Matrix'!I13/'Retention Count Matrix'!$B13,"")) | J24: =IF(EDATE($A24,J$12)>MAX(Customer_Month!$B:$B),"",IFERROR('Retention Count Matrix'!J13/'Retention Count Matrix'!$B13,"")) | K24: =IF(EDATE($A24,K$12)>MAX(Customer_Month!$B:$B),"",IFERROR('Retention Count Matrix'!K13/'Retention Count Matrix'!$B13,"")) | ... N24: =IF(EDATE($A24,N$12)>MAX(Customer_Month!$B:$B),"",IFERROR('Retention Count Matrix'!N13/'Retention Count Matrix'!$B13,""))
P28: KEY INSIGHTS
P30: • Month 1 retention averages 55.91%, meaning more than half of customers return in the following month.
P32: • Month 3 retention averages 44.45%, showing a gradual decline in repeat engagement.
P34: • Month 6 retention averages 26.21%, indicating that roughly one quarter of customers remain active after six months.
A36: Note: Retention is calculated as the percentage of customers who made at least one purchase in the given month after their first purchase. | P36: • Jan-2011 is the largest cohort with 192 customers.
P38: • Dec-2010 is the only cohort with a full 12-month observation window.
